Workbook

Sheet Summary Dashboard
A1: Summary Dashboard — All Territories
A2: Live cross-territory comparison. Year and Month selectors below.
A4: Year: | B4: 2026 | D4: Month: | E4: Apr | G4: ← change Year/Month to update all metrics below
A6: ▶ A. CURRENT MONTH — Goals vs Actual by Territory
A7: Territory | C7: Rev Goal | D7: Rev Actual | E7: % to Goal | F7: Member Goal | G7: New Members (T) | H7: New Members (NT) | I7: Drops (T) | J7: Drops (NT) | K7: Revenue Retention % (T + NT) | L7: Penetration % (Target) | M7: Account Retention % (T + NT)
A8: East King | C8: =IF(COUNTIFS('Data - Monthly Metrics'!A:A,$B$4,'Data - Monthly Metrics'!B:B,$E$4,'Data - Monthly Metrics'!C:C,"East King",'Data - Monthly Metrics'!D:D,"Goal - New Sales Revenue ($)")=0,"-",SUMIFS('Data - Monthly Metrics'!E:E,'Data - Monthly Metrics'!A:A,$B$4,'Data - Monthly Metrics'!B:B,$E$4,'Data - Monthly Metrics'!C:C,"East King",'Data - Monthly Metrics'!D:D,"Goal - New Sales Revenue ($)")) | D8: =IF(COUNTIFS('Data - Monthly Metrics'!A:A,$B$4,'Data - Monthly Metrics'!B:B,$E$4,'Data - Monthly Metrics'!C:C,"East King",'Data - Monthly Metrics'!D:D,"New Sales Revenue - Target ($)")+SUMIFS('Data - Monthly Metrics'!E:E,'Data - Monthly Metrics'!A:A,$B$4,'Data - Monthly Metrics'!B:B,$E$4,'Data - Monthly Metrics'!C:C,"East King",'Data - Monthly Metrics'!D:D,"New Sales Revenue - Non-Target ($)")=0,"-",SUMIFS('Data - Monthly Metrics'!E:E,'Data - Monthly Metrics'!A:A,$B$4,'Data - Monthly Metrics'!B:B,$E$4,'Data - Monthly Metrics'!C:C,"East King",'Data - Monthly Metrics'!D:D,"New Sales Revenue - Target ($)")+SUMIFS('Data - Monthly Metrics'!E:E,'Data - Monthly Metrics'!A:A,$B$4,'Data - Monthly Metrics'!B:B,$E$4,'Data - Monthly Metrics'!C:C,"East King",'Data - Monthly Metrics'!D:D,"New Sales Revenue - Non-Target ($)")) | E8: =IF(OR(NOT(ISNUMBER(C8)),C8=0),"-",D8/C8) | F8: =IF(COUNTIFS('Data - Monthly Metrics'!A:A,$B$4,'Data - Monthly Metrics'!B:B,$E$4,'Data - Monthly Metrics'!C:C,"East King",'Data - Monthly Metrics'!D:D,"Goal - New Members (#)")=0,"-",SUMIFS('Data - Monthly Metrics'!E:E,'Data - Monthly Metrics'!A:A,$B$4,'Data - Monthly Metrics'!B:B,$E$4,'Data - Monthly Metrics'!C:C,"East King",'Data - Monthly Metrics'!D:D,"Goal - New Members (#)")) | G8: =IF(COUNTIFS('Data - Monthly Metrics'!A:A,$B$4,'Data - Monthly Metrics'!B:B,$E$4,'Data - Monthly Metrics'!C:C,"East King",'Data - Monthly Metrics'!D:D,"New Members - Target (#)")=0,"-",SUMIFS('Data - Monthly Metrics'!E:E,'Data - Monthly Metrics'!A:A,$B$4,'Data - Monthly Metrics'!B:B,$E$4,'Data - Monthly Metrics'!C:C,"East King",'Data - Monthly Metrics'!D:D,"New Members - Target (#)")) | H8: =IF(COUNTIFS('Data - Monthly Metrics'!A:A,$B$4,'Data - Monthly Metrics'!B:B,$E$4,'Data - Monthly Metrics'!C:C,"East King",'Data - Monthly Metrics'!D:D,"New Members - Non-Target (#)")=0,"-",SUMIFS('Data - Monthly Metrics'!E:E,'Data - Monthly Metrics'!A:A,$B$4,'Data - Monthly Metrics'!B:B,$E$4,'Data - Monthly Metrics'!C:C,"East King",'Data - Monthly Metrics'!D:D,"New Members - Non-Target (#)")) | I8: =IF(COUNTIFS('Data - Monthly Metrics'!A:A,$B$4,'Data - Monthly Metrics'!B:B,$E$4,'Data - Monthly Metrics'!C:C,"East King",'Data - Monthly Metrics'!D:D,"Drops - Target (#)")=0,"-",SUMIFS('Data - Monthly Metrics'!E:E,'Data - Monthly Metrics'!A:A,$B$4,'Data - Monthly Metrics'!B:B,$E$4,'Data - Monthly Metrics'!C:C,"East King",'Data - Monthly Metrics'!D:D,"Drops - Target (#)")) | J8: =IF(COUNTIFS('Data - Monthly Metrics'!A:A,$B$4,'Data - Monthly Metrics'!B:B,$E$4,'Data - Monthly Metrics'!C:C,"East King",'Data - Monthly Metrics'!D:D,"Drops - Non-Target (#)")=0,"-",SUMIFS('Data - Monthly Metrics'!E:E,'Data - Monthly Metrics'!A:A,$B$4,'Data - Monthly Metrics'!B:B,$E$4,'Data - Monthly Metrics'!C:C,"East King",'Data - Monthly Metrics'!D:D,"Drops - Non-Target (#)")) | K8: =IFERROR((SUMIFS('Data - Monthly Metrics'!E:E,'Data - Monthly Metrics'!A:A,$B$4,'Data - Monthly Metrics'!B:B,$E$4,'Data - Monthly Metrics'!C:C,"East King",'Data - Monthly Metrics'!D:D,"Revenue Retained - Target ($)")+SUMIFS('Data - Monthly Metrics'!E:E,'Data - Monthly Metrics'!A:A,$B$4,'Data - Monthly Metrics'!B:B,$E$4,'Data - Monthly Metrics'!C:C,"East King",'Data - Monthly Metrics'!D:D,"Revenue Retained - Non-Target ($)"))/(SUMIFS('Data - Monthly Metrics'!E:E,'Data - Monthly Metrics'!A:A,$B$4,'Data - Monthly Metrics'!B:B,$E$4,'Data - Monthly Metrics'!C:C,"East King",'Data - Monthly Metrics'!D:D,"Revenue Up for Renewal - Target ($)")+SUMIFS('Data - Monthly Metrics'!E:E,'Data - Monthly Metrics'!A:A,$B$4,'Data - Monthly Metrics'!B:B,$E$4,'Data - Monthly Metrics'!C:C,"East King",'Data - Monthly Metrics'!D:D,"Revenue Up for Renewal - Non-Target ($)")),"-") | L8: =IF(COUNTIFS('Data - Monthly Metrics'!A:A,$B$4,'Data - Monthly Metrics'!B:B,$E$4,'Data - Monthly Metrics'!C:C,"East King",'Data - Monthly Metrics'!D:D,"Penetration - Combined %")=0,"-",SUMIFS('Data - Monthly Metrics'!E:E,'Data - Monthly Metrics'!A:A,$B$4,'Data - Monthly Metrics'!B:B,$E$4,'Data - Monthly Metrics'!C:C,"East King",'Data - Monthly Metrics'!D:D,"Penetration - Combined %")) | M8: =IFERROR((SUMIFS('Data - Monthly Metrics'!E:E,'Data - Monthly Metrics'!A:A,$B$4,'Data - Monthly Metrics'!B:B,$E$4,'Data - Monthly Metrics'!C:C,"East King",'Data - Monthly Metrics'!D:D,"Members Retained - Target (#)")+SUMIFS('Data - Monthly Metrics'!E:E,'Data - Monthly Metrics'!A:A,$B$4,'Data - Monthly Metrics'!B:B,$E$4,'Data - Monthly Metrics'!C:C,"East King",'Data - Monthly Metrics'!D:D,"Members Retained - Non-Target (#)"))/(SUMIFS('Data - Monthly Metrics'!E:E,'Data - Monthly Metrics'!A:A,$B$4,'Data - Monthly Metrics'!B:B,$E$4,'Data - Monthly Metrics'!C:C,"East King",'Data - Monthly Metrics'!D:D,"Members Up for Renewal - Target (#)")+SUMIFS('Data - Monthly Metrics'!E:E,'Data - Monthly Metrics'!A:A,$B$4,'Data - Monthly Metrics'!B:B,$E$4,'Data - Monthly Metrics'!C:C,"East King",'Data - Monthly Metrics'!D:D,"Members Up for Renewal - Non-Target (#)")),"-")
A9: South King | C9: =IF(COUNTIFS('Data - Monthly Metrics'!A:A,$B$4,'Data - Monthly Metrics'!B:B,$E$4,'Data - Monthly Metrics'!C:C,"South King",'Data - Monthly Metrics'!D:D,"Goal - New Sales Revenue ($)")=0,"-",SUMIFS('Data - Monthly Metrics'!E:E,'Data - Monthly Metrics'!A:A,$B$4,'Data - Monthly Metrics'!B:B,$E$4,'Data - Monthly Metrics'!C:C,"South King",'Data - Monthly Metrics'!D:D,"Goal - New Sales Revenue ($)")) | D9: =IF(COUNTIFS('Data - Monthly Metrics'!A:A,$B$4,'Data - Monthly Metrics'!B:B,$E$4,'Data - Monthly Metrics'!C:C,"South King",'Data - Monthly Metrics'!D:D,"New Sales Revenue - Target ($)")+SUMIFS('Data - Monthly Metrics'!E:E,'Data - Monthly Metrics'!A:A,$B$4,'Data - Monthly Metrics'!B:B,$E$4,'Data - Monthly Metrics'!C:C,"South King",'Data - Monthly Metrics'!D:D,"New Sales Revenue - Non-Target ($)")=0,"-",SUMIFS('Data - Monthly Metrics'!E:E,'Data - Monthly Metrics'!A:A,$B$4,'Data - Monthly Metrics'!B:B,$E$4,'Data - Monthly Metrics'!C:C,"South King",'Data - Monthly Metrics'!D:D,"New Sales Revenue - Target ($)")+SUMIFS('Data - Monthly Metrics'!E:E,'Data - Monthly Metrics'!A:A,$B$4,'Data - Monthly Metrics'!B:B,$E$4,'Data - Monthly Metrics'!C:C,"South King",'Data - Monthly Metrics'!D:D,"New Sales Revenue - Non-Target ($)")) | E9: =IF(OR(NOT(ISNUMBER(C9)),C9=0),"-",D9/C9) | F9: =IF(COUNTIFS('Data - Monthly Metrics'!A:A,$B$4,'Data - Monthly Metrics'!B:B,$E$4,'Data - Monthly Metrics'!C:C,"South King",'Data - Monthly Metrics'!D:D,"Goal - New Members (#)")=0,"-",SUMIFS('Data - Monthly Metrics'!E:E,'Data - Monthly Metrics'!A:A,$B$4,'Data - Monthly Metrics'!B:B,$E$4,'Data - Monthly Metrics'!C:C,"South King",'Data - Monthly Metrics'!D:D,"Goal - New Members (#)")) | G9: =IF(COUNTIFS('Data - Monthly Metrics'!A:A,$B$4,'Data - Monthly Metrics'!B:B,$E$4,'Data - Monthly Metrics'!C:C,"South King",'Data - Monthly Metrics'!D:D,"New Members - Target (#)")=0,"-",SUMIFS('Data - Monthly Metrics'!E:E,'Data - Monthly Metrics'!A:A,$B$4,'Data - Monthly Metrics'!B:B,$E$4,'Data - Monthly Metrics'!C:C,"South King",'Data - Monthly Metrics'!D:D,"New Members - Target (#)")) | H9: =IF(COUNTIFS('Data - Monthly Metrics'!A:A,$B$4,'Data - Monthly Metrics'!B:B,$E$4,'Data - Monthly Metrics'!C:C,"South King",'Data - Monthly Metrics'!D:D,"New Members - Non-Target (#)")=0,"-",SUMIFS('Data - Monthly Metrics'!E:E,'Data - Monthly Metrics'!A:A,$B$4,'Data - Monthly Metrics'!B:B,$E$4,'Data - Monthly Metrics'!C:C,"South King",'Data - Monthly Metrics'!D:D,"New Members - Non-Target (#)")) | I9: =IF(COUNTIFS('Data - Monthly Metrics'!A:A,$B$4,'Data - Monthly Metrics'!B:B,$E$4,'Data - Monthly Metrics'!C:C,"South King",'Data - Monthly Metrics'!D:D,"Drops - Target (#)")=0,"-",SUMIFS('Data - Monthly Metrics'!E:E,'Data - Monthly Metrics'!A:A,$B$4,'Data - Monthly Metrics'!B:B,$E$4,'Data - Monthly Metrics'!C:C,"South King",'Data - Monthly Metrics'!D:D,"Drops - Target (#)")) | J9: =IF(COUNTIFS('Data - Monthly Metrics'!A:A,$B$4,'Data - Monthly Metrics'!B:B,$E$4,'Data - Monthly Metrics'!C:C,"South King",'Data - Monthly Metrics'!D:D,"Drops - Non-Target (#)")=0,"-",SUMIFS('Data - Monthly Metrics'!E:E,'Data - Monthly Metrics'!A:A,$B$4,'Data - Monthly Metrics'!B:B,$E$4,'Data - Monthly Metrics'!C:C,"South King",'Data - Monthly Metrics'!D:D,"Drops - Non-Target (#)")) | K9: =IFERROR((SUMIFS('Data - Monthly Metrics'!E:E,'Data - Monthly Metrics'!A:A,$B$4,'Data - Monthly Metrics'!B:B,$E$4,'Data - Monthly Metrics'!C:C,"South King",'Data - Monthly Metrics'!D:D,"Revenue Retained - Target ($)")+SUMIFS('Data - Monthly Metrics'!E:E,'Data - Monthly Metrics'!A:A,$B$4,'Data - Monthly Metrics'!B:B,$E$4,'Data - Monthly Metrics'!C:C,"South King",'Data - Monthly Metrics'!D:D,"Revenue Retained - Non-Target ($)"))/(SUMIFS('Data - Monthly Metrics'!E:E,'Data - Monthly Metrics'!A:A,$B$4,'Data - Monthly Metrics'!B:B,$E$4,'Data - Monthly Metrics'!C:C,"South King",'Data - Monthly Metrics'!D:D,"Revenue Up for Renewal - Target ($)")+SUMIFS('Data - Monthly Metrics'!E:E,'Data - Monthly Metrics'!A:A,$B$4,'Data - Monthly Metrics'!B:B,$E$4,'Data - Monthly Metrics'!C:C,"South King",'Data - Monthly Metrics'!D:D,"Revenue Up for Renewal - Non-Target ($)")),"-") | L9: =IF(COUNTIFS('Data - Monthly Metrics'!A:A,$B$4,'Data - Monthly Metrics'!B:B,$E$4,'Data - Monthly Metrics'!C:C,"South King",'Data - Monthly Metrics'!D:D,"Penetration - Combined %")=0,"-",SUMIFS('Data - Monthly Metrics'!E:E,'Data - Monthly Metrics'!A:A,$B$4,'Data - Monthly Metrics'!B:B,$E$4,'Data - Monthly Metrics'!C:C,"South King",'Data - Monthly Metrics'!D:D,"Penetration - Combined %")) | M9: =IFERROR((SUMIFS('Data - Monthly Metrics'!E:E,'Data - Monthly Metrics'!A:A,$B$4,'Data - Monthly Metrics'!B:B,$E$4,'Data - Monthly Metrics'!C:C,"South King",'Data - Monthly Metrics'!D:D,"Members Retained - Target (#)")+SUMIFS('Data - Monthly Metrics'!E:E,'Data - Monthly Metrics'!A:A,$B$4,'Data - Monthly Metrics'!B:B,$E$4,'Data - Monthly Metrics'!C:C,"South King",'Data - Monthly Metrics'!D:D,"Members Retained - Non-Target (#)"))/(SUMIFS('Data - Monthly Metrics'!E:E,'Data - Monthly Metrics'!A:A,$B$4,'Data - Monthly Metrics'!B:B,$E$4,'Data - Monthly Metrics'!C:C,"South King",'Data - Monthly Metrics'!D:D,"Members Up for Renewal - Target (#)")+SUMIFS('Data - Monthly Metrics'!E:E,'Data - Monthly Metrics'!A:A,$B$4,'Data - Monthly Metrics'!B:B,$E$4,'Data - Monthly Metrics'!C:C,"South King",'Data - Monthly Metrics'!D:D,"Members Up for Renewal - Non-Target (#)")),"-")
A10: North King | C10: =IF(COUNTIFS('Data - Monthly Metrics'!A:A,$B$4,'Data - Monthly Metrics'!B:B,$E$4,'Data - Monthly Metrics'!C:C,"North King",'Data - Monthly Metrics'!D:D,"Goal - New Sales Revenue ($)")=0,"-",SUMIFS('Data - Monthly Metrics'!E:E,'Data - Monthly Metrics'!A:A,$B$4,'Data - Monthly Metrics'!B:B,$E$4,'Data - Monthly Metrics'!C:C,"North King",'Data - Monthly Metrics'!D:D,"Goal - New Sales Revenue ($)")) | D10: =IF(COUNTIFS('Data - Monthly Metrics'!A:A,$B$4,'Data - Monthly Metrics'!B:B,$E$4,'Data - Monthly Metrics'!C:C,"North King",'Data - Monthly Metrics'!D:D,"New Sales Revenue - Target ($)")+SUMIFS('Data - Monthly Metrics'!E:E,'Data - Monthly Metrics'!A:A,$B$4,'Data - Monthly Metrics'!B:B,$E$4,'Data - Monthly Metrics'!C:C,"North King",'Data - Monthly Metrics'!D:D,"New Sales Revenue - Non-Target ($)")=0,"-",SUMIFS('Data - Monthly Metrics'!E:E,'Data - Monthly Metrics'!A:A,$B$4,'Data - Monthly Metrics'!B:B,$E$4,'Data - Monthly Metrics'!C:C,"North King",'Data - Monthly Metrics'!D:D,"New Sales Revenue - Target ($)")+SUMIFS('Data - Monthly Metrics'!E:E,'Data - Monthly Metrics'!A:A,$B$4,'Data - Monthly Metrics'!B:B,$E$4,'Data - Monthly Metrics'!C:C,"North King",'Data - Monthly Metrics'!D:D,"New Sales Revenue - Non-Target ($)")) | E10: =IF(OR(NOT(ISNUMBER(C10)),C10=0),"-",D10/C10) | F10: =IF(COUNTIFS('Data - Monthly Metrics'!A:A,$B$4,'Data - Monthly Metrics'!B:B,$E$4,'Data - Monthly Metrics'!C:C,"North King",'Data - Monthly Metrics'!D:D,"Goal - New Members (#)")=0,"-",SUMIFS('Data - Monthly Metrics'!E:E,'Data - Monthly Metrics'!A:A,$B$4,'Data - Monthly Metrics'!B:B,$E$4,'Data - Monthly Metrics'!C:C,"North King",'Data - Monthly Metrics'!D:D,"Goal - New Members (#)")) | G10: =IF(COUNTIFS('Data - Monthly Metrics'!A:A,$B$4,'Data - Monthly Metrics'!B:B,$E$4,'Data - Monthly Metrics'!C:C,"North King",'Data - Monthly Metrics'!D:D,"New Members - Target (#)")=0,"-",SUMIFS('Data - Monthly Metrics'!E:E,'Data - Monthly Metrics'!A:A,$B$4,'Data - Monthly Metrics'!B:B,$E$4,'Data - Monthly Metrics'!C:C,"North King",'Data - Monthly Metrics'!D:D,"New Members - Target (#)")) | H10: =IF(COUNTIFS('Data - Monthly Metrics'!A:A,$B$4,'Data - Monthly Metrics'!B:B,$E$4,'Data - Monthly Metrics'!C:C,"North King",'Data - Monthly Metrics'!D:D,"New Members - Non-Target (#)")=0,"-",SUMIFS('Data - Monthly Metrics'!E:E,'Data - Monthly Metrics'!A:A,$B$4,'Data - Monthly Metrics'!B:B,$E$4,'Data - Monthly Metrics'!C:C,"North King",'Data - Monthly Metrics'!D:D,"New Members - Non-Target (#)")) | I10: =IF(COUNTIFS('Data - Monthly Metrics'!A:A,$B$4,'Data - Monthly Metrics'!B:B,$E$4,'Data - Monthly Metrics'!C:C,"North King",'Data - Monthly Metrics'!D:D,"Drops - Target (#)")=0,"-",SUMIFS('Data - Monthly Metrics'!E:E,'Data - Monthly Metrics'!A:A,$B$4,'Data - Monthly Metrics'!B:B,$E$4,'Data - Monthly Metrics'!C:C,"North King",'Data - Monthly Metrics'!D:D,"Drops - Target (#)")) | J10: =IF(COUNTIFS('Data - Monthly Metrics'!A:A,$B$4,'Data - Monthly Metrics'!B:B,$E$4,'Data - Monthly Metrics'!C:C,"North King",'Data - Monthly Metrics'!D:D,"Drops - Non-Target (#)")=0,"-",SUMIFS('Data - Monthly Metrics'!E:E,'Data - Monthly Metrics'!A:A,$B$4,'Data - Monthly Metrics'!B:B,$E$4,'Data - Monthly Metrics'!C:C,"North King",'Data - Monthly Metrics'!D:D,"Drops - Non-Target (#)")) | K10: =IFERROR((SUMIFS('Data - Monthly Metrics'!E:E,'Data - Monthly Metrics'!A:A,$B$4,'Data - Monthly Metrics'!B:B,$E$4,'Data - Monthly Metrics'!C:C,"North King",'Data - Monthly Metrics'!D:D,"Revenue Retained - Target ($)")+SUMIFS('Data - Monthly Metrics'!E:E,'Data - Monthly Metrics'!A:A,$B$4,'Data - Monthly Metrics'!B:B,$E$4,'Data - Monthly Metrics'!C:C,"North King",'Data - Monthly Metrics'!D:D,"Revenue Retained - Non-Target ($)"))/(SUMIFS('Data - Monthly Metrics'!E:E,'Data - Monthly Metrics'!A:A,$B$4,'Data - Monthly Metrics'!B:B,$E$4,'Data - Monthly Metrics'!C:C,"North King",'Data - Monthly Metrics'!D:D,"Revenue Up for Renewal - Target ($)")+SUMIFS('Data - Monthly Metrics'!E:E,'Data - Monthly Metrics'!A:A,$B$4,'Data - Monthly Metrics'!B:B,$E$4,'Data - Monthly Metrics'!C:C,"North King",'Data - Monthly Metrics'!D:D,"Revenue Up for Renewal - Non-Target ($)")),"-") | L10: =IF(COUNTIFS('Data - Monthly Metrics'!A:A,$B$4,'Data - Monthly Metrics'!B:B,$E$4,'Data - Monthly Metrics'!C:C,"North King",'Data - Monthly Metrics'!D:D,"Penetration - Combined %")=0,"-",SUMIFS('Data - Monthly Metrics'!E:E,'Data - Monthly Metrics'!A:A,$B$4,'Data - Monthly Metrics'!B:B,$E$4,'Data - Monthly Metrics'!C:C,"North King",'Data - Monthly Metrics'!D:D,"Penetration - Combined %")) | M10: =IFERROR((SUMIFS('Data - Monthly Metrics'!E:E,'Data - Monthly Metrics'!A:A,$B$4,'Data - Monthly Metrics'!B:B,$E$4,'Data - Monthly Metrics'!C:C,"North King",'Data - Monthly Metrics'!D:D,"Members Retained - Target (#)")+SUMIFS('Data - Monthly Metrics'!E:E,'Data - Monthly Metrics'!A:A,$B$4,'Data - Monthly Metrics'!B:B,$E$4,'Data - Monthly Metrics'!C:C,"North King",'Data - Monthly Metrics'!D:D,"Members Retained - Non-Target (#)"))/(SUMIFS('Data - Monthly Metrics'!E:E,'Data - Monthly Metrics'!A:A,$B$4,'Data - Monthly Metrics'!B:B,$E$4,'Data - Monthly Metrics'!C:C,"North King",'Data - Monthly Metrics'!D:D,"Members Up for Renewal - Target (#)")+SUMIFS('Data - Monthly Metrics'!E:E,'Data - Monthly Metrics'!A:A,$B$4,'Data - Monthly Metrics'!B:B,$E$4,'Data - Monthly Metrics'!C:C,"North King",'Data - Monthly Metrics'!D:D,"Members Up for Renewal - Non-Target (#)")),"-")
A11: Pierce | C11: =IF(COUNTIFS('Data - Monthly Metrics'!A:A,$B$4,'Data - Monthly Metrics'!B:B,$E$4,'Data - Monthly Metrics'!C:C,"Pierce",'Data - Monthly Metrics'!D:D,"Goal - New Sales Revenue ($)")=0,"-",SUMIFS('Data - Monthly Metrics'!E:E,'Data - Monthly Metrics'!A:A,$B$4,'Data - Monthly Metrics'!B:B,$E$4,'Data - Monthly Metrics'!C:C,"Pierce",'Data - Monthly Metrics'!D:D,"Goal - New Sales Revenue ($)")) | D11: =IF(COUNTIFS('Data - Monthly Metrics'!A:A,$B$4,'Data - Monthly Metrics'!B:B,$E$4,'Data - Monthly Metrics'!C:C,"Pierce",'Data - Monthly Metrics'!D:D,"New Sales Revenue - Target ($)")+SUMIFS('Data - Monthly Metrics'!E:E,'Data - Monthly Metrics'!A:A,$B$4,'Data - Monthly Metrics'!B:B,$E$4,'Data - Monthly Metrics'!C:C,"Pierce",'Data - Monthly Metrics'!D:D,"New Sales Revenue - Non-Target ($)")=0,"-",SUMIFS('Data - Monthly Metrics'!E:E,'Data - Monthly Metrics'!A:A,$B$4,'Data - Monthly Metrics'!B:B,$E$4,'Data - Monthly Metrics'!C:C,"Pierce",'Data - Monthly Metrics'!D:D,"New Sales Revenue - Target ($)")+SUMIFS('Data - Monthly Metrics'!E:E,'Data - Monthly Metrics'!A:A,$B$4,'Data - Monthly Metrics'!B:B,$E$4,'Data - Monthly Metrics'!C:C,"Pierce",'Data - Monthly Metrics'!D:D,"New Sales Revenue - Non-Target ($)")) | E11: =IF(OR(NOT(ISNUMBER(C11)),C11=0),"-",D11/C11) | F11: =IF(COUNTIFS('Data - Monthly Metrics'!A:A,$B$4,'Data - Monthly Metrics'!B:B,$E$4,'Data - Monthly Metrics'!C:C,"Pierce",'Data - Monthly Metrics'!D:D,"Goal - New Members (#)")=0,"-",SUMIFS('Data - Monthly Metrics'!E:E,'Data - Monthly Metrics'!A:A,$B$4,'Data - Monthly Metrics'!B:B,$E$4,'Data - Monthly Metrics'!C:C,"Pierce",'Data - Monthly Metrics'!D:D,"Goal - New Members (#)")) | G11: =IF(COUNTIFS('Data - Monthly Metrics'!A:A,$B$4,'Data - Monthly Metrics'!B:B,$E$4,'Data - Monthly Metrics'!C:C,"Pierce",'Data - Monthly Metrics'!D:D,"New Members - Target (#)")=0,"-",SUMIFS('Data - Monthly Metrics'!E:E,'Data - Monthly Metrics'!A:A,$B$4,'Data - Monthly Metrics'!B:B,$E$4,'Data - Monthly Metrics'!C:C,"Pierce",'Data - Monthly Metrics'!D:D,"New Members - Target (#)")) | H11: =IF(COUNTIFS('Data - Monthly Metrics'!A:A,$B$4,'Data - Monthly Metrics'!B:B,$E$4,'Data - Monthly Metrics'!C:C,"Pierce",'Data - Monthly Metrics'!D:D,"New Members - Non-Target (#)")=0,"-",SUMIFS('Data - Monthly Metrics'!E:E,'Data - Monthly Metrics'!A:A,$B$4,'Data - Monthly Metrics'!B:B,$E$4,'Data - Monthly Metrics'!C:C,"Pierce",'Data - Monthly Metrics'!D:D,"New Members - Non-Target (#)")) | I11: =IF(COUNTIFS('Data - Monthly Metrics'!A:A,$B$4,'Data - Monthly Metrics'!B:B,$E$4,'Data - Monthly Metrics'!C:C,"Pierce",'Data - Monthly Metrics'!D:D,"Drops - Target (#)")=0,"-",SUMIFS('Data - Monthly Metrics'!E:E,'Data - Monthly Metrics'!A:A,$B$4,'Data - Monthly Metrics'!B:B,$E$4,'Data - Monthly Metrics'!C:C,"Pierce",'Data - Monthly Metrics'!D:D,"Drops - Target (#)")) | J11: =IF(COUNTIFS('Data - Monthly Metrics'!A:A,$B$4,'Data - Monthly Metrics'!B:B,$E$4,'Data - Monthly Metrics'!C:C,"Pierce",'Data - Monthly Metrics'!D:D,"Drops - Non-Target (#)")=0,"-",SUMIFS('Data - Monthly Metrics'!E:E,'Data - Monthly Metrics'!A:A,$B$4,'Data - Monthly Metrics'!B:B,$E$4,'Data - Monthly Metrics'!C:C,"Pierce",'Data - Monthly Metrics'!D:D,"Drops - Non-Target (#)")) | K11: =IFERROR((SUMIFS('Data - Monthly Metrics'!E:E,'Data - Monthly Metrics'!A:A,$B$4,'Data - Monthly Metrics'!B:B,$E$4,'Data - Monthly Metrics'!C:C,"Pierce",'Data - Monthly Metrics'!D:D,"Revenue Retained - Target ($)")+SUMIFS('Data - Monthly Metrics'!E:E,'Data - Monthly Metrics'!A:A,$B$4,'Data - Monthly Metrics'!B:B,$E$4,'Data - Monthly Metrics'!C:C,"Pierce",'Data - Monthly Metrics'!D:D,"Revenue Retained - Non-Target ($)"))/(SUMIFS('Data - Monthly Metrics'!E:E,'Data - Monthly Metrics'!A:A,$B$4,'Data - Monthly Metrics'!B:B,$E$4,'Data - Monthly Metrics'!C:C,"Pierce",'Data - Monthly Metrics'!D:D,"Revenue Up for Renewal - Target ($)")+SUMIFS('Data - Monthly Metrics'!E:E,'Data - Monthly Metrics'!A:A,$B$4,'Data - Monthly Metrics'!B:B,$E$4,'Data - Monthly Metrics'!C:C,"Pierce",'Data - Monthly Metrics'!D:D,"Revenue Up for Renewal - Non-Target ($)")),"-") | L11: =IF(COUNTIFS('Data - Monthly Metrics'!A:A,$B$4,'Data - Monthly Metrics'!B:B,$E$4,'Data - Monthly Metrics'!C:C,"Pierce",'Data - Monthly Metrics'!D:D,"Penetration - Combined %")=0,"-",SUMIFS('Data - Monthly Metrics'!E:E,'Data - Monthly Metrics'!A:A,$B$4,'Data - Monthly Metrics'!B:B,$E$4,'Data - Monthly Metrics'!C:C,"Pierce",'Data - Monthly Metrics'!D:D,"Penetration - Combined %")) | M11: =IFERROR((SUMIFS('Data - Monthly Metrics'!E:E,'Data - Monthly Metrics'!A:A,$B$4,'Data - Monthly Metrics'!B:B,$E$4,'Data - Monthly Metrics'!C:C,"Pierce",'Data - Monthly Metrics'!D:D,"Members Retained - Target (#)")+SUMIFS('Data - Monthly Metrics'!E:E,'Data - Monthly Metrics'!A:A,$B$4,'Data - Monthly Metrics'!B:B,$E$4,'Data - Monthly Metrics'!C:C,"Pierce",'Data - Monthly Metrics'!D:D,"Members Retained - Non-Target (#)"))/(SUMIFS('Data - Monthly Metrics'!E:E,'Data - Monthly Metrics'!A:A,$B$4,'Data - Monthly Metrics'!B:B,$E$4,'Data - Monthly Metrics'!C:C,"Pierce",'Data - Monthly Metrics'!D:D,"Members Up for Renewal - Target (#)")+SUMIFS('Data - Monthly Metrics'!E:E,'Data - Monthly Metrics'!A:A,$B$4,'Data - Monthly Metrics'!B:B,$E$4,'Data - Monthly Metrics'!C:C,"Pierce",'Data - Monthly Metrics'!D:D,"Members Up for Renewal - Non-Target (#)")),"-")
A12: Snohomish | C12: =IF(COUNTIFS('Data - Monthly Metrics'!A:A,$B$4,'Data - Monthly Metrics'!B:B,$E$4,'Data - Monthly Metrics'!C:C,"Snohomish",'Data - Monthly Metrics'!D:D,"Goal - New Sales Revenue ($)")=0,"-",SUMIFS('Data - Monthly Metrics'!E:E,'Data - Monthly Metrics'!A:A,$B$4,'Data - Monthly Metrics'!B:B,$E$4,'Data - Monthly Metrics'!C:C,"Snohomish",'Data - Monthly Metrics'!D:D,"Goal - New Sales Revenue ($)")) | D12: =IF(COUNTIFS('Data - Monthly Metrics'!A:A,$B$4,'Data - Monthly Metrics'!B:B,$E$4,'Data - Monthly Metrics'!C:C,"Snohomish",'Data - Monthly Metrics'!D:D,"New Sales Revenue - Target ($)")+SUMIFS('Data - Monthly Metrics'!E:E,'Data - Monthly Metrics'!A:A,$B$4,'Data - Monthly Metrics'!B:B,$E$4,'Data - Monthly Metrics'!C:C,"Snohomish",'Data - Monthly Metrics'!D:D,"New Sales Revenue - Non-Target ($)")=0,"-",SUMIFS('Data - Monthly Metrics'!E:E,'Data - Monthly Metrics'!A:A,$B$4,'Data - Monthly Metrics'!B:B,$E$4,'Data - Monthly Metrics'!C:C,"Snohomish",'Data - Monthly Metrics'!D:D,"New Sales Revenue - Target ($)")+SUMIFS('Data - Monthly Metrics'!E:E,'Data - Monthly Metrics'!A:A,$B$4,'Data - Monthly Metrics'!B:B,$E$4,'Data - Monthly Metrics'!C:C,"Snohomish",'Data - Monthly Metrics'!D:D,"New Sales Revenue - Non-Target ($)")) | E12: =IF(OR(NOT(ISNUMBER(C12)),C12=0),"-",D12/C12) | F12: =IF(COUNTIFS('Data - Monthly Metrics'!A:A,$B$4,'Data - Monthly Metrics'!B:B,$E$4,'Data - Monthly Metrics'!C:C,"Snohomish",'Data - Monthly Metrics'!D:D,"Goal - New Members (#)")=0,"-",SUMIFS('Data - Monthly Metrics'!E:E,'Data - Monthly Metrics'!A:A,$B$4,'Data - Monthly Metrics'!B:B,$E$4,'Data - Monthly Metrics'!C:C,"Snohomish",'Data - Monthly Metrics'!D:D,"Goal - New Members (#)")) | G12: =IF(COUNTIFS('Data - Monthly Metrics'!A:A,$B$4,'Data - Monthly Metrics'!B:B,$E$4,'Data - Monthly Metrics'!C:C,"Snohomish",'Data - Monthly Metrics'!D:D,"New Members - Target (#)")=0,"-",SUMIFS('Data - Monthly Metrics'!E:E,'Data - Monthly Metrics'!A:A,$B$4,'Data - Monthly Metrics'!B:B,$E$4,'Data - Monthly Metrics'!C:C,"Snohomish",'Data - Monthly Metrics'!D:D,"New Members - Target (#)")) | H12: =IF(COUNTIFS('Data - Monthly Metrics'!A:A,$B$4,'Data - Monthly Metrics'!B:B,$E$4,'Data - Monthly Metrics'!C:C,"Snohomish",'Data - Monthly Metrics'!D:D,"New Members - Non-Target (#)")=0,"-",SUMIFS('Data - Monthly Metrics'!E:E,'Data - Monthly Metrics'!A:A,$B$4,'Data - Monthly Metrics'!B:B,$E$4,'Data - Monthly Metrics'!C:C,"Snohomish",'Data - Monthly Metrics'!D:D,"New Members - Non-Target (#)")) | I12: =IF(COUNTIFS('Data - Monthly Metrics'!A:A,$B$4,'Data - Monthly Metrics'!B:B,$E$4,'Data - Monthly Metrics'!C:C,"Snohomish",'Data - Monthly Metrics'!D:D,"Drops - Target (#)")=0,"-",SUMIFS('Data - Monthly Metrics'!E:E,'Data - Monthly Metrics'!A:A,$B$4,'Data - Monthly Metrics'!B:B,$E$4,'Data - Monthly Metrics'!C:C,"Snohomish",'Data - Monthly Metrics'!D:D,"Drops - Target (#)")) | J12: =IF(COUNTIFS('Data - Monthly Metrics'!A:A,$B$4,'Data - Monthly Metrics'!B:B,$E$4,'Data - Monthly Metrics'!C:C,"Snohomish",'Data - Monthly Metrics'!D:D,"Drops - Non-Target (#)")=0,"-",SUMIFS('Data - Monthly Metrics'!E:E,'Data - Monthly Metrics'!A:A,$B$4,'Data - Monthly Metrics'!B:B,$E$4,'Data - Monthly Metrics'!C:C,"Snohomish",'Data - Monthly Metrics'!D:D,"Drops - Non-Target (#)")) | K12: =IFERROR((SUMIFS('Data - Monthly Metrics'!E:E,'Data - Monthly Metrics'!A:A,$B$4,'Data - Monthly Metrics'!B:B,$E$4,'Data - Monthly Metrics'!C:C,"Snohomish",'Data - Monthly Metrics'!D:D,"Revenue Retained - Target ($)")+SUMIFS('Data - Monthly Metrics'!E:E,'Data - Monthly Metrics'!A:A,$B$4,'Data - Monthly Metrics'!B:B,$E$4,'Data - Monthly Metrics'!C:C,"Snohomish",'Data - Monthly Metrics'!D:D,"Revenue Retained - Non-Target ($)"))/(SUMIFS('Data - Monthly Metrics'!E:E,'Data - Monthly Metrics'!A:A,$B$4,'Data - Monthly Metrics'!B:B,$E$4,'Data - Monthly Metrics'!C:C,"Snohomish",'Data - Monthly Metrics'!D:D,"Revenue Up for Renewal - Target ($)")+SUMIFS('Data - Monthly Metrics'!E:E,'Data - Monthly Metrics'!A:A,$B$4,'Data - Monthly Metrics'!B:B,$E$4,'Data - Monthly Metrics'!C:C,"Snohomish",'Data - Monthly Metrics'!D:D,"Revenue Up for Renewal - Non-Target ($)")),"-") | L12: =IF(COUNTIFS('Data - Monthly Metrics'!A:A,$B$4,'Data - Monthly Metrics'!B:B,$E$4,'Data - Monthly Metrics'!C:C,"Snohomish",'Data - Monthly Metrics'!D:D,"Penetration - Combined %")=0,"-",SUMIFS('Data - Monthly Metrics'!E:E,'Data - Monthly Metrics'!A:A,$B$4,'Data - Monthly Metrics'!B:B,$E$4,'Data - Monthly Metrics'!C:C,"Snohomish",'Data - Monthly Metrics'!D:D,"Penetration - Combined %")) | M12: =IFERROR((SUMIFS('Data - Monthly Metrics'!E:E,'Data - Monthly Metrics'!A:A,$B$4,'Data - Monthly Metrics'!B:B,$E$4,'Data - Monthly Metrics'!C:C,"Snohomish",'Data - Monthly Metrics'!D:D,"Members Retained - Target (#)")+SUMIFS('Data - Monthly Metrics'!E:E,'Data - Monthly Metrics'!A:A,$B$4,'Data - Monthly Metrics'!B:B,$E$4,'Data - Monthly Metrics'!C:C,"Snohomish",'Data - Monthly Metrics'!D:D,"Members Retained - Non-Target (#)"))/(SUMIFS('Data - Monthly Metrics'!E:E,'Data - Monthly Metrics'!A:A,$B$4,'Data - Monthly Metrics'!B:B,$E$4,'Data - Monthly Metrics'!C:C,"Snohomish",'Data - Monthly Metrics'!D:D,"Members Up for Renewal - Target (#)")+SUMIFS('Data - Monthly Metrics'!E:E,'Data - Monthly Metrics'!A:A,$B$4,'Data - Monthly Metrics'!B:B,$E$4,'Data - Monthly Metrics'!C:C,"Snohomish",'Data - Monthly Metrics'!D:D,"Members Up for Renewal - Non-Target (#)")),"-")
A13: Spokane/NE | C13: =IF(COUNTIFS('Data - Monthly Metrics'!A:A,$B$4,'Data - Monthly Metrics'!B:B,$E$4,'Data - Monthly Metrics'!C:C,"Spokane/NE",'Data - Monthly Metrics'!D:D,"Goal - New Sales Revenue ($)")=0,"-",SUMIFS('Data - Monthly Metrics'!E:E,'Data - Monthly Metrics'!A:A,$B$4,'Data - Monthly Metrics'!B:B,$E$4,'Data - Monthly Metrics'!C:C,"Spokane/NE",'Data - Monthly Metrics'!D:D,"Goal - New Sales Revenue ($)")) | D13: =IF(COUNTIFS('Data - Monthly Metrics'!A:A,$B$4,'Data - Monthly Metrics'!B:B,$E$4,'Data - Monthly Metrics'!C:C,"Spokane/NE",'Data - Monthly Metrics'!D:D,"New Sales Revenue - Target ($)")+SUMIFS('Data - Monthly Metrics'!E:E,'Data - Monthly Metrics'!A:A,$B$4,'Data - Monthly Metrics'!B:B,$E$4,'Data - Monthly Metrics'!C:C,"Spokane/NE",'Data - Monthly Metrics'!D:D,"New Sales Revenue - Non-Target ($)")=0,"-",SUMIFS('Data - Monthly Metrics'!E:E,'Data - Monthly Metrics'!A:A,$B$4,'Data - Monthly Metrics'!B:B,$E$4,'Data - Monthly Metrics'!C:C,"Spokane/NE",'Data - Monthly Metrics'!D:D,"New Sales Revenue - Target ($)")+SUMIFS('Data - Monthly Metrics'!E:E,'Data - Monthly Metrics'!A:A,$B$4,'Data - Monthly Metrics'!B:B,$E$4,'Data - Monthly Metrics'!C:C,"Spokane/NE",'Data - Monthly Metrics'!D:D,"New Sales Revenue - Non-Target ($)")) | E13: =IF(OR(NOT(ISNUMBER(C13)),C13=0),"-",D13/C13) | F13: =IF(COUNTIFS('Data - Monthly Metrics'!A:A,$B$4,'Data - Monthly Metrics'!B:B,$E$4,'Data - Monthly Metrics'!C:C,"Spokane/NE",'Data - Monthly Metrics'!D:D,"Goal - New Members (#)")=0,"-",SUMIFS('Data - Monthly Metrics'!E:E,'Data - Monthly Metrics'!A:A,$B$4,'Data - Monthly Metrics'!B:B,$E$4,'Data - Monthly Metrics'!C:C,"Spokane/NE",'Data - Monthly Metrics'!D:D,"Goal - New Members (#)")) | G13: =IF(COUNTIFS('Data - Monthly Metrics'!A:A,$B$4,'Data - Monthly Metrics'!B:B,$E$4,'Data - Monthly Metrics'!C:C,"Spokane/NE",'Data - Monthly Metrics'!D:D,"New Members - Target (#)")=0,"-",SUMIFS('Data - Monthly Metrics'!E:E,'Data - Monthly Metrics'!A:A,$B$4,'Data - Monthly Metrics'!B:B,$E$4,'Data - Monthly Metrics'!C:C,"Spokane/NE",'Data - Monthly Metrics'!D:D,"New Members - Target (#)")) | H13: =IF(COUNTIFS('Data - Monthly Metrics'!A:A,$B$4,'Data - Monthly Metrics'!B:B,$E$4,'Data - Monthly Metrics'!C:C,"Spokane/NE",'Data - Monthly Metrics'!D:D,"New Members - Non-Target (#)")=0,"-",SUMIFS('Data - Monthly Metrics'!E:E,'Data - Monthly Metrics'!A:A,$B$4,'Data - Monthly Metrics'!B:B,$E$4,'Data - Monthly Metrics'!C:C,"Spokane/NE",'Data - Monthly Metrics'!D:D,"New Members - Non-Target (#)")) | I13: =IF(COUNTIFS('Data - Monthly Metrics'!A:A,$B$4,'Data - Monthly Metrics'!B:B,$E$4,'Data - Monthly Metrics'!C:C,"Spokane/NE",'Data - Monthly Metrics'!D:D,"Drops - Target (#)")=0,"-",SUMIFS('Data - Monthly Metrics'!E:E,'Data - Monthly Metrics'!A:A,$B$4,'Data - Monthly Metrics'!B:B,$E$4,'Data - Monthly Metrics'!C:C,"Spokane/NE",'Data - Monthly Metrics'!D:D,"Drops - Target (#)")) | J13: =IF(COUNTIFS('Data - Monthly Metrics'!A:A,$B$4,'Data - Monthly Metrics'!B:B,$E$4,'Data - Monthly Metrics'!C:C,"Spokane/NE",'Data - Monthly Metrics'!D:D,"Drops - Non-Target (#)")=0,"-",SUMIFS('Data - Monthly Metrics'!E:E,'Data - Monthly Metrics'!A:A,$B$4,'Data - Monthly Metrics'!B:B,$E$4,'Data - Monthly Metrics'!C:C,"Spokane/NE",'Data - Monthly Metrics'!D:D,"Drops - Non-Target (#)")) | K13: =IFERROR((SUMIFS('Data - Monthly Metrics'!E:E,'Data - Monthly Metrics'!A:A,$B$4,'Data - Monthly Metrics'!B:B,$E$4,'Data - Monthly Metrics'!C:C,"Spokane/NE",'Data - Monthly Metrics'!D:D,"Revenue Retained - Target ($)")+SUMIFS('Data - Monthly Metrics'!E:E,'Data - Monthly Metrics'!A:A,$B$4,'Data - Monthly Metrics'!B:B,$E$4,'Data - Monthly Metrics'!C:C,"Spokane/NE",'Data - Monthly Metrics'!D:D,"Revenue Retained - Non-Target ($)"))/(SUMIFS('Data - Monthly Metrics'!E:E,'Data - Monthly Metrics'!A:A,$B$4,'Data - Monthly Metrics'!B:B,$E$4,'Data - Monthly Metrics'!C:C,"Spokane/NE",'Data - Monthly Metrics'!D:D,"Revenue Up for Renewal - Target ($)")+SUMIFS('Data - Monthly Metrics'!E:E,'Data - Monthly Metrics'!A:A,$B$4,'Data - Monthly Metrics'!B:B,$E$4,'Data - Monthly Metrics'!C:C,"Spokane/NE",'Data - Monthly Metrics'!D:D,"Revenue Up for Renewal - Non-Target ($)")),"-") | L13: =IF(COUNTIFS('Data - Monthly Metrics'!A:A,$B$4,'Data - Monthly Metrics'!B:B,$E$4,'Data - Monthly Metrics'!C:C,"Spokane/NE",'Data - Monthly Metrics'!D:D,"Penetration - Combined %")=0,"-",SUMIFS('Data - Monthly Metrics'!E:E,'Data - Monthly Metrics'!A:A,$B$4,'Data - Monthly Metrics'!B:B,$E$4,'Data - Monthly Metrics'!C:C,"Spokane/NE",'Data - Monthly Metrics'!D:D,"Penetration - Combined %")) | M13: =IFERROR((SUMIFS('Data - Monthly Metrics'!E:E,'Data - Monthly Metrics'!A:A,$B$4,'Data - Monthly Metrics'!B:B,$E$4,'Data - Monthly Metrics'!C:C,"Spokane/NE",'Data - Monthly Metrics'!D:D,"Members Retained - Target (#)")+SUMIFS('Data - Monthly Metrics'!E:E,'Data - Monthly Metrics'!A:A,$B$4,'Data - Monthly Metrics'!B:B,$E$4,'Data - Monthly Metrics'!C:C,"Spokane/NE",'Data - Monthly Metrics'!D:D,"Members Retained - Non-Target (#)"))/(SUMIFS('Data - Monthly Metrics'!E:E,'Data - Monthly Metrics'!A:A,$B$4,'Data - Monthly Metrics'!B:B,$E$4,'Data - Monthly Metrics'!C:C,"Spokane/NE",'Data - Monthly Metrics'!D:D,"Members Up for Renewal - Target (#)")+SUMIFS('Data - Monthly Metrics'!E:E,'Data - Monthly Metrics'!A:A,$B$4,'Data - Monthly Metrics'!B:B,$E$4,'Data - Monthly Metrics'!C:C,"Spokane/NE",'Data - Monthly Metrics'!D:D,"Members Up for Renewal - Non-Target (#)")),"-")
A14: Southwest | C14: =IF(COUNTIFS('Data - Monthly Metrics'!A:A,$B$4,'Data - Monthly Metrics'!B:B,$E$4,'Data - Monthly Metrics'!C:C,"Southwest",'Data - Monthly Metrics'!D:D,"Goal - New Sales Revenue ($)")=0,"-",SUMIFS('Data - Monthly Metrics'!E:E,'Data - Monthly Metrics'!A:A,$B$4,'Data - Monthly Metrics'!B:B,$E$4,'Data - Monthly Metrics'!C:C,"Southwest",'Data - Monthly Metrics'!D:D,"Goal - New Sales Revenue ($)")) | D14: =IF(COUNTIFS('Data - Monthly Metrics'!A:A,$B$4,'Data - Monthly Metrics'!B:B,$E$4,'Data - Monthly Metrics'!C:C,"Southwest",'Data - Monthly Metrics'!D:D,"New Sales Revenue - Target ($)")+SUMIFS('Data - Monthly Metrics'!E:E,'Data - Monthly Metrics'!A:A,$B$4,'Data - Monthly Metrics'!B:B,$E$4,'Data - Monthly Metrics'!C:C,"Southwest",'Data - Monthly Metrics'!D:D,"New Sales Revenue - Non-Target ($)")=0,"-",SUMIFS('Data - Monthly Metrics'!E:E,'Data - Monthly Metrics'!A:A,$B$4,'Data - Monthly Metrics'!B:B,$E$4,'Data - Monthly Metrics'!C:C,"Southwest",'Data - Monthly Metrics'!D:D,"New Sales Revenue - Target ($)")+SUMIFS('Data - Monthly Metrics'!E:E,'Data - Monthly Metrics'!A:A,$B$4,'Data - Monthly Metrics'!B:B,$E$4,'Data - Monthly Metrics'!C:C,"Southwest",'Data - Monthly Metrics'!D:D,"New Sales Revenue - Non-Target ($)")) | E14: =IF(OR(NOT(ISNUMBER(C14)),C14=0),"-",D14/C14) | F14: =IF(COUNTIFS('Data - Monthly Metrics'!A:A,$B$4,'Data - Monthly Metrics'!B:B,$E$4,'Data - Monthly Metrics'!C:C,"Southwest",'Data - Monthly Metrics'!D:D,"Goal - New Members (#)")=0,"-",SUMIFS('Data - Monthly Metrics'!E:E,'Data - Monthly Metrics'!A:A,$B$4,'Data - Monthly Metrics'!B:B,$E$4,'Data - Monthly Metrics'!C:C,"Southwest",'Data - Monthly Metrics'!D:D,"Goal - New Members (#)")) | G14: =IF(COUNTIFS('Data - Monthly Metrics'!A:A,$B$4,'Data - Monthly Metrics'!B:B,$E$4,'Data - Monthly Metrics'!C:C,"Southwest",'Data - Monthly Metrics'!D:D,"New Members - Target (#)")=0,"-",SUMIFS('Data - Monthly Metrics'!E:E,'Data - Monthly Metrics'!A:A,$B$4,'Data - Monthly Metrics'!B:B,$E$4,'Data - Monthly Metrics'!C:C,"Southwest",'Data - Monthly Metrics'!D:D,"New Members - Target (#)")) | H14: =IF(COUNTIFS('Data - Monthly Metrics'!A:A,$B$4,'Data - Monthly Metrics'!B:B,$E$4,'Data - Monthly Metrics'!C:C,"Southwest",'Data - Monthly Metrics'!D:D,"New Members - Non-Target (#)")=0,"-",SUMIFS('Data - Monthly Metrics'!E:E,'Data - Monthly Metrics'!A:A,$B$4,'Data - Monthly Metrics'!B:B,$E$4,'Data - Monthly Metrics'!C:C,"Southwest",'Data - Monthly Metrics'!D:D,"New Members - Non-Target (#)")) | I14: =IF(COUNTIFS('Data - Monthly Metrics'!A:A,$B$4,'Data - Monthly Metrics'!B:B,$E$4,'Data - Monthly Metrics'!C:C,"Southwest",'Data - Monthly Metrics'!D:D,"Drops - Target (#)")=0,"-",SUMIFS('Data - Monthly Metrics'!E:E,'Data - Monthly Metrics'!A:A,$B$4,'Data - Monthly Metrics'!B:B,$E$4,'Data - Monthly Metrics'!C:C,"Southwest",'Data - Monthly Metrics'!D:D,"Drops - Target (#)")) | J14: =IF(COUNTIFS('Data - Monthly Metrics'!A:A,$B$4,'Data - Monthly Metrics'!B:B,$E$4,'Data - Monthly Metrics'!C:C,"Southwest",'Data - Monthly Metrics'!D:D,"Drops - Non-Target (#)")=0,"-",SUMIFS('Data - Monthly Metrics'!E:E,'Data - Monthly Metrics'!A:A,$B$4,'Data - Monthly Metrics'!B:B,$E$4,'Data - Monthly Metrics'!C:C,"Southwest",'Data - Monthly Metrics'!D:D,"Drops - Non-Target (#)")) | K14: =IFERROR((SUMIFS('Data - Monthly Metrics'!E:E,'Data - Monthly Metrics'!A:A,$B$4,'Data - Monthly Metrics'!B:B,$E$4,'Data - Monthly Metrics'!C:C,"Southwest",'Data - Monthly Metrics'!D:D,"Revenue Retained - Target ($)")+SUMIFS('Data - Monthly Metrics'!E:E,'Data - Monthly Metrics'!A:A,$B$4,'Data - Monthly Metrics'!B:B,$E$4,'Data - Monthly Metrics'!C:C,"Southwest",'Data - Monthly Metrics'!D:D,"Revenue Retained - Non-Target ($)"))/(SUMIFS('Data - Monthly Metrics'!E:E,'Data - Monthly Metrics'!A:A,$B$4,'Data - Monthly Metrics'!B:B,$E$4,'Data - Monthly Metrics'!C:C,"Southwest",'Data - Monthly Metrics'!D:D,"Revenue Up for Renewal - Target ($)")+SUMIFS('Data - Monthly Metrics'!E:E,'Data - Monthly Metrics'!A:A,$B$4,'Data - Monthly Metrics'!B:B,$E$4,'Data - Monthly Metrics'!C:C,"Southwest",'Data - Monthly Metrics'!D:D,"Revenue Up for Renewal - Non-Target ($)")),"-") | L14: =IF(COUNTIFS('Data - Monthly Metrics'!A:A,$B$4,'Data - Monthly Metrics'!B:B,$E$4,'Data - Monthly Metrics'!C:C,"Southwest",'Data - Monthly Metrics'!D:D,"Penetration - Combined %")=0,"-",SUMIFS('Data - Monthly Metrics'!E:E,'Data - Monthly Metrics'!A:A,$B$4,'Data - Monthly Metrics'!B:B,$E$4,'Data - Monthly Metrics'!C:C,"Southwest",'Data - Monthly Metrics'!D:D,"Penetration - Combined %")) | M14: =IFERROR((SUMIFS('Data - Monthly Metrics'!E:E,'Data - Monthly Metrics'!A:A,$B$4,'Data - Monthly Metrics'!B:B,$E$4,'Data - Monthly Metrics'!C:C,"Southwest",'Data - Monthly Metrics'!D:D,"Members Retained - Target (#)")+SUMIFS('Data - Monthly Metrics'!E:E,'Data - Monthly Metrics'!A:A,$B$4,'Data - Monthly Metrics'!B:B,$E$4,'Data - Monthly Metrics'!C:C,"Southwest",'Data - Monthly Metrics'!D:D,"Members Retained - Non-Target (#)"))/(SUMIFS('Data - Monthly Metrics'!E:E,'Data - Monthly Metrics'!A:A,$B$4,'Data - Monthly Metrics'!B:B,$E$4,'Data - Monthly Metrics'!C:C,"Southwest",'Data - Monthly Metrics'!D:D,"Members Up for Renewal - Target (#)")+SUMIFS('Data - Monthly Metrics'!E:E,'Data - Monthly Metrics'!A:A,$B$4,'Data - Monthly Metrics'!B:B,$E$4,'Data - Monthly Metrics'!C:C,"Southwest",'Data - Monthly Metrics'!D:D,"Members Up for Renewal - Non-Target (#)")),"-")
A15: TKP | C15: =IF(COUNTIFS('Data - Monthly Metrics'!A:A,$B$4,'Data - Monthly Metrics'!B:B,$E$4,'Data - Monthly Metrics'!C:C,"TKP",'Data - Monthly Metrics'!D:D,"Goal - New Sales Revenue ($)")=0,"-",SUMIFS('Data - Monthly Metrics'!E:E,'Data - Monthly Metrics'!A:A,$B$4,'Data - Monthly Metrics'!B:B,$E$4,'Data - Monthly Metrics'!C:C,"TKP",'Data - Monthly Metrics'!D:D,"Goal - New Sales Revenue ($)")) | D15: =IF(COUNTIFS('Data - Monthly Metrics'!A:A,$B$4,'Data - Monthly Metrics'!B:B,$E$4,'Data - Monthly Metrics'!C:C,"TKP",'Data - Monthly Metrics'!D:D,"New Sales Revenue - Target ($)")+SUMIFS('Data - Monthly Metrics'!E:E,'Data - Monthly Metrics'!A:A,$B$4,'Data - Monthly Metrics'!B:B,$E$4,'Data - Monthly Metrics'!C:C,"TKP",'Data - Monthly Metrics'!D:D,"New Sales Revenue - Non-Target ($)")=0,"-",SUMIFS('Data - Monthly Metrics'!E:E,'Data - Monthly Metrics'!A:A,$B$4,'Data - Monthly Metrics'!B:B,$E$4,'Data - Monthly Metrics'!C:C,"TKP",'Data - Monthly Metrics'!D:D,"New Sales Revenue - Target ($)")+SUMIFS('Data - Monthly Metrics'!E:E,'Data - Monthly Metrics'!A:A,$B$4,'Data - Monthly Metrics'!B:B,$E$4,'Data - Monthly Metrics'!C:C,"TKP",'Data - Monthly Metrics'!D:D,"New Sales Revenue - Non-Target ($)")) | E15: =IF(OR(NOT(ISNUMBER(C15)),C15=0),"-",D15/C15) | F15: =IF(COUNTIFS('Data - Monthly Metrics'!A:A,$B$4,'Data - Monthly Metrics'!B:B,$E$4,'Data - Monthly Metrics'!C:C,"TKP",'Data - Monthly Metrics'!D:D,"Goal - New Members (#)")=0,"-",SUMIFS('Data - Monthly Metrics'!E:E,'Data - Monthly Metrics'!A:A,$B$4,'Data - Monthly Metrics'!B:B,$E$4,'Data - Monthly Metrics'!C:C,"TKP",'Data - Monthly Metrics'!D:D,"Goal - New Members (#)")) | G15: =IF(COUNTIFS('Data - Monthly Metrics'!A:A,$B$4,'Data - Monthly Metrics'!B:B,$E$4,'Data - Monthly Metrics'!C:C,"TKP",'Data - Monthly Metrics'!D:D,"New Members - Target (#)")=0,"-",SUMIFS('Data - Monthly Metrics'!E:E,'Data - Monthly Metrics'!A:A,$B$4,'Data - Monthly Metrics'!B:B,$E$4,'Data - Monthly Metrics'!C:C,"TKP",'Data - Monthly Metrics'!D:D,"New Members - Target (#)")) | H15: =IF(COUNTIFS('Data - Monthly Metrics'!A:A,$B$4,'Data - Monthly Metrics'!B:B,$E$4,'Data - Monthly Metrics'!C:C,"TKP",'Data - Monthly Metrics'!D:D,"New Members - Non-Target (#)")=0,"-",SUMIFS('Data - Monthly Metrics'!E:E,'Data - Monthly Metrics'!A:A,$B$4,'Data - Monthly Metrics'!B:B,$E$4,'Data - Monthly Metrics'!C:C,"TKP",'Data - Monthly Metrics'!D:D,"New Members - Non-Target (#)")) | I15: =IF(COUNTIFS('Data - Monthly Metrics'!A:A,$B$4,'Data - Monthly Metrics'!B:B,$E$4,'Data - Monthly Metrics'!C:C,"TKP",'Data - Monthly Metrics'!D:D,"Drops - Target (#)")=0,"-",SUMIFS('Data - Monthly Metrics'!E:E,'Data - Monthly Metrics'!A:A,$B$4,'Data - Monthly Metrics'!B:B,$E$4,'Data - Monthly Metrics'!C:C,"TKP",'Data - Monthly Metrics'!D:D,"Drops - Target (#)")) | J15: =IF(COUNTIFS('Data - Monthly Metrics'!A:A,$B$4,'Data - Monthly Metrics'!B:B,$E$4,'Data - Monthly Metrics'!C:C,"TKP",'Data - Monthly Metrics'!D:D,"Drops - Non-Target (#)")=0,"-",SUMIFS('Data - Monthly Metrics'!E:E,'Data - Monthly Metrics'!A:A,$B$4,'Data - Monthly Metrics'!B:B,$E$4,'Data - Monthly Metrics'!C:C,"TKP",'Data - Monthly Metrics'!D:D,"Drops - Non-Target (#)")) | K15: =IFERROR((SUMIFS('Data - Monthly Metrics'!E:E,'Data - Monthly Metrics'!A:A,$B$4,'Data - Monthly Metrics'!B:B,$E$4,'Data - Monthly Metrics'!C:C,"TKP",'Data - Monthly Metrics'!D:D,"Revenue Retained - Target ($)")+SUMIFS('Data - Monthly Metrics'!E:E,'Data - Monthly Metrics'!A:A,$B$4,'Data - Monthly Metrics'!B:B,$E$4,'Data - Monthly Metrics'!C:C,"TKP",'Data - Monthly Metrics'!D:D,"Revenue Retained - Non-Target ($)"))/(SUMIFS('Data - Monthly Metrics'!E:E,'Data - Monthly Metrics'!A:A,$B$4,'Data - Monthly Metrics'!B:B,$E$4,'Data - Monthly Metrics'!C:C,"TKP",'Data - Monthly Metrics'!D:D,"Revenue Up for Renewal - Target ($)")+SUMIFS('Data - Monthly Metrics'!E:E,'Data - Monthly Metrics'!A:A,$B$4,'Data - Monthly Metrics'!B:B,$E$4,'Data - Monthly Metrics'!C:C,"TKP",'Data - Monthly Metrics'!D:D,"Revenue Up for Renewal - Non-Target ($)")),"-") | L15: =IF(COUNTIFS('Data - Monthly Metrics'!A:A,$B$4,'Data - Monthly Metrics'!B:B,$E$4,'Data - Monthly Metrics'!C:C,"TKP",'Data - Monthly Metrics'!D:D,"Penetration - Combined %")=0,"-",SUMIFS('Data - Monthly Metrics'!E:E,'Data - Monthly Metrics'!A:A,$B$4,'Data - Monthly Metrics'!B:B,$E$4,'Data - Monthly Metrics'!C:C,"TKP",'Data - Monthly Metrics'!D:D,"Penetration - Combined %")) | M15: =IFERROR((SUMIFS('Data - Monthly Metrics'!E:E,'Data - Monthly Metrics'!A:A,$B$4,'Data - Monthly Metrics'!B:B,$E$4,'Data - Monthly Metrics'!C:C,"TKP",'Data - Monthly Metrics'!D:D,"Members Retained - Target (#)")+SUMIFS('Data - Monthly Metrics'!E:E,'Data - Monthly Metrics'!A:A,$B$4,'Data - Monthly Metrics'!B:B,$E$4,'Data - Monthly Metrics'!C:C,"TKP",'Data - Monthly Metrics'!D:D,"Members Retained - Non-Target (#)"))/(SUMIFS('Data - Monthly Metrics'!E:E,'Data - Monthly Metrics'!A:A,$B$4,'Data - Monthly Metrics'!B:B,$E$4,'Data - Monthly Metrics'!C:C,"TKP",'Data - Monthly Metrics'!D:D,"Members Up for Renewal - Target (#)")+SUMIFS('Data - Monthly Metrics'!E:E,'Data - Monthly Metrics'!A:A,$B$4,'Data - Monthly Metrics'!B:B,$E$4,'Data - Monthly Metrics'!C:C,"TKP",'Data - Monthly Metrics'!D:D,"Members Up for Renewal - Non-Target (#)")),"-")
A16: Southeast | C16: =IF(COUNTIFS('Data - Monthly Metrics'!A:A,$B$4,'Data - Monthly Metrics'!B:B,$E$4,'Data - Monthly Metrics'!C:C,"Southeast",'Data - Monthly Metrics'!D:D,"Goal - New Sales Revenue ($)")=0,"-",SUMIFS('Data - Monthly Metrics'!E:E,'Data - Monthly Metrics'!A:A,$B$4,'Data - Monthly Metrics'!B:B,$E$4,'Data - Monthly Metrics'!C:C,"Southeast",'Data - Monthly Metrics'!D:D,"Goal - New Sales Revenue ($)")) | D16: =IF(COUNTIFS('Data - Monthly Metrics'!A:A,$B$4,'Data - Monthly Metrics'!B:B,$E$4,'Data - Monthly Metrics'!C:C,"Southeast",'Data - Monthly Metrics'!D:D,"New Sales Revenue - Target ($)")+SUMIFS('Data - Monthly Metrics'!E:E,'Data - Monthly Metrics'!A:A,$B$4,'Data - Monthly Metrics'!B:B,$E$4,'Data - Monthly Metrics'!C:C,"Southeast",'Data - Monthly Metrics'!D:D,"New Sales Revenue - Non-Target ($)")=0,"-",SUMIFS('Data - Monthly Metrics'!E:E,'Data - Monthly Metrics'!A:A,$B$4,'Data - Monthly Metrics'!B:B,$E$4,'Data - Monthly Metrics'!C:C,"Southeast",'Data - Monthly Metrics'!D:D,"New Sales Revenue - Target ($)")+SUMIFS('Data - Monthly Metrics'!E:E,'Data - Monthly Metrics'!A:A,$B$4,'Data - Monthly Metrics'!B:B,$E$4,'Data - Monthly Metrics'!C:C,"Southeast",'Data - Monthly Metrics'!D:D,"New Sales Revenue - Non-Target ($)")) | E16: =IF(OR(NOT(ISNUMBER(C16)),C16=0),"-",D16/C16) | F16: =IF(COUNTIFS('Data - Monthly Metrics'!A:A,$B$4,'Data - Monthly Metrics'!B:B,$E$4,'Data - Monthly Metrics'!C:C,"Southeast",'Data - Monthly Metrics'!D:D,"Goal - New Members (#)")=0,"-",SUMIFS('Data - Monthly Metrics'!E:E,'Data - Monthly Metrics'!A:A,$B$4,'Data - Monthly Metrics'!B:B,$E$4,'Data - Monthly Metrics'!C:C,"Southeast",'Data - Monthly Metrics'!D:D,"Goal - New Members (#)")) | G16: =IF(COUNTIFS('Data - Monthly Metrics'!A:A,$B$4,'Data - Monthly Metrics'!B:B,$E$4,'Data - Monthly Metrics'!C:C,"Southeast",'Data - Monthly Metrics'!D:D,"New Members - Target (#)")=0,"-",SUMIFS('Data - Monthly Metrics'!E:E,'Data - Monthly Metrics'!A:A,$B$4,'Data - Monthly Metrics'!B:B,$E$4,'Data - Monthly Metrics'!C:C,"Southeast",'Data - Monthly Metrics'!D:D,"New Members - Target (#)")) | H16: =IF(COUNTIFS('Data - Monthly Metrics'!A:A,$B$4,'Data - Monthly Metrics'!B:B,$E$4,'Data - Monthly Metrics'!C:C,"Southeast",'Data - Monthly Metrics'!D:D,"New Members - Non-Target (#)")=0,"-",SUMIFS('Data - Monthly Metrics'!E:E,'Data - Monthly Metrics'!A:A,$B$4,'Data - Monthly Metrics'!B:B,$E$4,'Data - Monthly Metrics'!C:C,"Southeast",'Data - Monthly Metrics'!D:D,"New Members - Non-Target (#)")) | I16: =IF(COUNTIFS('Data - Monthly Metrics'!A:A,$B$4,'Data - Monthly Metrics'!B:B,$E$4,'Data - Monthly Metrics'!C:C,"Southeast",'Data - Monthly Metrics'!D:D,"Drops - Target (#)")=0,"-",SUMIFS('Data - Monthly Metrics'!E:E,'Data - Monthly Metrics'!A:A,$B$4,'Data - Monthly Metrics'!B:B,$E$4,'Data - Monthly Metrics'!C:C,"Southeast",'Data - Monthly Metrics'!D:D,"Drops - Target (#)")) | J16: =IF(COUNTIFS('Data - Monthly Metrics'!A:A,$B$4,'Data - Monthly Metrics'!B:B,$E$4,'Data - Monthly Metrics'!C:C,"Southeast",'Data - Monthly Metrics'!D:D,"Drops - Non-Target (#)")=0,"-",SUMIFS('Data - Monthly Metrics'!E:E,'Data - Monthly Metrics'!A:A,$B$4,'Data - Monthly Metrics'!B:B,$E$4,'Data - Monthly Metrics'!C:C,"Southeast",'Data - Monthly Metrics'!D:D,"Drops - Non-Target (#)")) | K16: =IFERROR((SUMIFS('Data - Monthly Metrics'!E:E,'Data - Monthly Metrics'!A:A,$B$4,'Data - Monthly Metrics'!B:B,$E$4,'Data - Monthly Metrics'!C:C,"Southeast",'Data - Monthly Metrics'!D:D,"Revenue Retained - Target ($)")+SUMIFS('Data - Monthly Metrics'!E:E,'Data - Monthly Metrics'!A:A,$B$4,'Data - Monthly Metrics'!B:B,$E$4,'Data - Monthly Metrics'!C:C,"Southeast",'Data - Monthly Metrics'!D:D,"Revenue Retained - Non-Target ($)"))/(SUMIFS('Data - Monthly Metrics'!E:E,'Data - Monthly Metrics'!A:A,$B$4,'Data - Monthly Metrics'!B:B,$E$4,'Data - Monthly Metrics'!C:C,"Southeast",'Data - Monthly Metrics'!D:D,"Revenue Up for Renewal - Target ($)")+SUMIFS('Data - Monthly Metrics'!E:E,'Data - Monthly Metrics'!A:A,$B$4,'Data - Monthly Metrics'!B:B,$E$4,'Data - Monthly Metrics'!C:C,"Southeast",'Data - Monthly Metrics'!D:D,"Revenue Up for Renewal - Non-Target ($)")),"-") | L16: =IF(COUNTIFS('Data - Monthly Metrics'!A:A,$B$4,'Data - Monthly Metrics'!B:B,$E$4,'Data - Monthly Metrics'!C:C,"Southeast",'Data - Monthly Metrics'!D:D,"Penetration - Combined %")=0,"-",SUMIFS('Data - Monthly Metrics'!E:E,'Data - Monthly Metrics'!A:A,$B$4,'Data - Monthly Metrics'!B:B,$E$4,'Data - Monthly Metrics'!C:C,"Southeast",'Data - Monthly Metrics'!D:D,"Penetration - Combined %")) | M16: =IFERROR((SUMIFS('Data - Monthly Metrics'!E:E,'Data - Monthly Metrics'!A:A,$B$4,'Data - Monthly Metrics'!B:B,$E$4,'Data - Monthly Metrics'!C:C,"Southeast",'Data - Monthly Metrics'!D:D,"Members Retained - Target (#)")+SUMIFS('Data - Monthly Metrics'!E:E,'Data - Monthly Metrics'!A:A,$B$4,'Data - Monthly Metrics'!B:B,$E$4,'Data - Monthly Metrics'!C:C,"Southeast",'Data - Monthly Metrics'!D:D,"Members Retained - Non-Target (#)"))/(SUMIFS('Data - Monthly Metrics'!E:E,'Data - Monthly Metrics'!A:A,$B$4,'Data - Monthly Metrics'!B:B,$E$4,'Data - Monthly Metrics'!C:C,"Southeast",'Data - Monthly Metrics'!D:D,"Members Up for Renewal - Target (#)")+SUMIFS('Data - Monthly Metrics'!E:E,'Data - Monthly Metrics'!A:A,$B$4,'Data - Monthly Metrics'!B:B,$E$4,'Data - Monthly Metrics'!C:C,"Southeast",'Data - Monthly Metrics'!D:D,"Members Up for Renewal - Non-Target (#)")),"-")
A17: NorthCentral | C17: =IF(COUNTIFS('Data - Monthly Metrics'!A:A,$B$4,'Data - Monthly Metrics'!B:B,$E$4,'Data - Monthly Metrics'!C:C,"NorthCentral",'Data - Monthly Metrics'!D:D,"Goal - New Sales Revenue ($)")=0,"-",SUMIFS('Data - Monthly Metrics'!E:E,'Data - Monthly Metrics'!A:A,$B$4,'Data - Monthly Metrics'!B:B,$E$4,'Data - Monthly Metrics'!C:C,"NorthCentral",'Data - Monthly Metrics'!D:D,"Goal - New Sales Revenue ($)")) | D17: =IF(COUNTIFS('Data - Monthly Metrics'!A:A,$B$4,'Data - Monthly Metrics'!B:B,$E$4,'Data - Monthly Metrics'!C:C,"NorthCentral",'Data - Monthly Metrics'!D:D,"New Sales Revenue - Target ($)")+SUMIFS('Data - Monthly Metrics'!E:E,'Data - Monthly Metrics'!A:A,$B$4,'Data - Monthly Metrics'!B:B,$E$4,'Data - Monthly Metrics'!C:C,"NorthCentral",'Data - Monthly Metrics'!D:D,"New Sales Revenue - Non-Target ($)")=0,"-",SUMIFS('Data - Monthly Metrics'!E:E,'Data - Monthly Metrics'!A:A,$B$4,'Data - Monthly Metrics'!B:B,$E$4,'Data - Monthly Metrics'!C:C,"NorthCentral",'Data - Monthly Metrics'!D:D,"New Sales Revenue - Target ($)")+SUMIFS('Data - Monthly Metrics'!E:E,'Data - Monthly Metrics'!A:A,$B$4,'Data - Monthly Metrics'!B:B,$E$4,'Data - Monthly Metrics'!C:C,"NorthCentral",'Data - Monthly Metrics'!D:D,"New Sales Revenue - Non-Target ($)")) | E17: =IF(OR(NOT(ISNUMBER(C17)),C17=0),"-",D17/C17) | F17: =IF(COUNTIFS('Data - Monthly Metrics'!A:A,$B$4,'Data - Monthly Metrics'!B:B,$E$4,'Data - Monthly Metrics'!C:C,"NorthCentral",'Data - Monthly Metrics'!D:D,"Goal - New Members (#)")=0,"-",SUMIFS('Data - Monthly Metrics'!E:E,'Data - Monthly Metrics'!A:A,$B$4,'Data - Monthly Metrics'!B:B,$E$4,'Data - Monthly Metrics'!C:C,"NorthCentral",'Data - Monthly Metrics'!D:D,"Goal - New Members (#)")) | G17: =IF(COUNTIFS('Data - Monthly Metrics'!A:A,$B$4,'Data - Monthly Metrics'!B:B,$E$4,'Data - Monthly Metrics'!C:C,"NorthCentral",'Data - Monthly Metrics'!D:D,"New Members - Target (#)")=0,"-",SUMIFS('Data - Monthly Metrics'!E:E,'Data - Monthly Metrics'!A:A,$B$4,'Data - Monthly Metrics'!B:B,$E$4,'Data - Monthly Metrics'!C:C,"NorthCentral",'Data - Monthly Metrics'!D:D,"New Members - Target (#)")) | H17: =IF(COUNTIFS('Data - Monthly Metrics'!A:A,$B$4,'Data - Monthly Metrics'!B:B,$E$4,'Data - Monthly Metrics'!C:C,"NorthCentral",'Data - Monthly Metrics'!D:D,"New Members - Non-Target (#)")=0,"-",SUMIFS('Data - Monthly Metrics'!E:E,'Data - Monthly Metrics'!A:A,$B$4,'Data - Monthly Metrics'!B:B,$E$4,'Data - Monthly Metrics'!C:C,"NorthCentral",'Data - Monthly Metrics'!D:D,"New Members - Non-Target (#)")) | I17: =IF(COUNTIFS('Data - Monthly Metrics'!A:A,$B$4,'Data - Monthly Metrics'!B:B,$E$4,'Data - Monthly Metrics'!C:C,"NorthCentral",'Data - Monthly Metrics'!D:D,"Drops - Target (#)")=0,"-",SUMIFS('Data - Monthly Metrics'!E:E,'Data - Monthly Metrics'!A:A,$B$4,'Data - Monthly Metrics'!B:B,$E$4,'Data - Monthly Metrics'!C:C,"NorthCentral",'Data - Monthly Metrics'!D:D,"Drops - Target (#)")) | J17: =IF(COUNTIFS('Data - Monthly Metrics'!A:A,$B$4,'Data - Monthly Metrics'!B:B,$E$4,'Data - Monthly Metrics'!C:C,"NorthCentral",'Data - Monthly Metrics'!D:D,"Drops - Non-Target (#)")=0,"-",SUMIFS('Data - Monthly Metrics'!E:E,'Data - Monthly Metrics'!A:A,$B$4,'Data - Monthly Metrics'!B:B,$E$4,'Data - Monthly Metrics'!C:C,"NorthCentral",'Data - Monthly Metrics'!D:D,"Drops - Non-Target (#)")) | K17: =IFERROR((SUMIFS('Data - Monthly Metrics'!E:E,'Data - Monthly Metrics'!A:A,$B$4,'Data - Monthly Metrics'!B:B,$E$4,'Data - Monthly Metrics'!C:C,"NorthCentral",'Data - Monthly Metrics'!D:D,"Revenue Retained - Target ($)")+SUMIFS('Data - Monthly Metrics'!E:E,'Data - Monthly Metrics'!A:A,$B$4,'Data - Monthly Metrics'!B:B,$E$4,'Data - Monthly Metrics'!C:C,"NorthCentral",'Data - Monthly Metrics'!D:D,"Revenue Retained - Non-Target ($)"))/(SUMIFS('Data - Monthly Metrics'!E:E,'Data - Monthly Metrics'!A:A,$B$4,'Data - Monthly Metrics'!B:B,$E$4,'Data - Monthly Metrics'!C:C,"NorthCentral",'Data - Monthly Metrics'!D:D,"Revenue Up for Renewal - Target ($)")+SUMIFS('Data - Monthly Metrics'!E:E,'Data - Monthly Metrics'!A:A,$B$4,'Data - Monthly Metrics'!B:B,$E$4,'Data - Monthly Metrics'!C:C,"NorthCentral",'Data - Monthly Metrics'!D:D,"Revenue Up for Renewal - Non-Target ($)")),"-") | L17: =IF(COUNTIFS('Data - Monthly Metrics'!A:A,$B$4,'Data - Monthly Metrics'!B:B,$E$4,'Data - Monthly Metrics'!C:C,"NorthCentral",'Data - Monthly Metrics'!D:D,"Penetration - Combined %")=0,"-",SUMIFS('Data - Monthly Metrics'!E:E,'Data - Monthly Metrics'!A:A,$B$4,'Data - Monthly Metrics'!B:B,$E$4,'Data - Monthly Metrics'!C:C,"NorthCentral",'Data - Monthly Metrics'!D:D,"Penetration - Combined %")) | M17: =IFERROR((SUMIFS('Data - Monthly Metrics'!E:E,'Data - Monthly Metrics'!A:A,$B$4,'Data - Monthly Metrics'!B:B,$E$4,'Data - Monthly Metrics'!C:C,"NorthCentral",'Data - Monthly Metrics'!D:D,"Members Retained - Target (#)")+SUMIFS('Data - Monthly Metrics'!E:E,'Data - Monthly Metrics'!A:A,$B$4,'Data - Monthly Metrics'!B:B,$E$4,'Data - Monthly Metrics'!C:C,"NorthCentral",'Data - Monthly Metrics'!D:D,"Members Retained - Non-Target (#)"))/(SUMIFS('Data - Monthly Metrics'!E:E,'Data - Monthly Metrics'!A:A,$B$4,'Data - Monthly Metrics'!B:B,$E$4,'Data - Monthly Metrics'!C:C,"NorthCentral",'Data - Monthly Metrics'!D:D,"Members Up for Renewal - Target (#)")+SUMIFS('Data - Monthly Metrics'!E:E,'Data - Monthly Metrics'!A:A,$B$4,'Data - Monthly Metrics'!B:B,$E$4,'Data - Monthly Metrics'!C:C,"NorthCentral",'Data - Monthly Metrics'!D:D,"Members Up for Renewal - Non-Target (#)")),"-")
A18: Majors/NRA | C18: =IF(COUNTIFS('Data - Monthly Metrics'!A:A,$B$4,'Data - Monthly Metrics'!B:B,$E$4,'Data - Monthly Metrics'!C:C,"Majors/NRA",'Data - Monthly Metrics'!D:D,"Goal - New Sales Revenue ($)")=0,"-",SUMIFS('Data - Monthly Metrics'!E:E,'Data - Monthly Metrics'!A:A,$B$4,'Data - Monthly Metrics'!B:B,$E$4,'Data - Monthly Metrics'!C:C,"Majors/NRA",'Data - Monthly Metrics'!D:D,"Goal - New Sales Revenue ($)")) | D18: =IF(COUNTIFS('Data - Monthly Metrics'!A:A,$B$4,'Data - Monthly Metrics'!B:B,$E$4,'Data - Monthly Metrics'!C:C,"Majors/NRA",'Data - Monthly Metrics'!D:D,"New Sales Revenue - Target ($)")+SUMIFS('Data - Monthly Metrics'!E:E,'Data - Monthly Metrics'!A:A,$B$4,'Data - Monthly Metrics'!B:B,$E$4,'Data - Monthly Metrics'!C:C,"Majors/NRA",'Data - Monthly Metrics'!D:D,"New Sales Revenue - Non-Target ($)")=0,"-",SUMIFS('Data - Monthly Metrics'!E:E,'Data - Monthly Metrics'!A:A,$B$4,'Data - Monthly Metrics'!B:B,$E$4,'Data - Monthly Metrics'!C:C,"Majors/NRA",'Data - Monthly Metrics'!D:D,"New Sales Revenue - Target ($)")+SUMIFS('Data - Monthly Metrics'!E:E,'Data - Monthly Metrics'!A:A,$B$4,'Data - Monthly Metrics'!B:B,$E$4,'Data - Monthly Metrics'!C:C,"Majors/NRA",'Data - Monthly Metrics'!D:D,"New Sales Revenue - Non-Target ($)")) | E18: =IF(OR(NOT(ISNUMBER(C18)),C18=0),"-",D18/C18) | F18: =IF(COUNTIFS('Data - Monthly Metrics'!A:A,$B$4,'Data - Monthly Metrics'!B:B,$E$4,'Data - Monthly Metrics'!C:C,"Majors/NRA",'Data - Monthly Metrics'!D:D,"Goal - New Members (#)")=0,"-",SUMIFS('Data - Monthly Metrics'!E:E,'Data - Monthly Metrics'!A:A,$B$4,'Data - Monthly Metrics'!B:B,$E$4,'Data - Monthly Metrics'!C:C,"Majors/NRA",'Data - Monthly Metrics'!D:D,"Goal - New Members (#)")) | G18: =IF(COUNTIFS('Data - Monthly Metrics'!A:A,$B$4,'Data - Monthly Metrics'!B:B,$E$4,'Data - Monthly Metrics'!C:C,"Majors/NRA",'Data - Monthly Metrics'!D:D,"New Members - Target (#)")=0,"-",SUMIFS('Data - Monthly Metrics'!E:E,'Data - Monthly Metrics'!A:A,$B$4,'Data - Monthly Metrics'!B:B,$E$4,'Data - Monthly Metrics'!C:C,"Majors/NRA",'Data - Monthly Metrics'!D:D,"New Members - Target (#)")) | H18: =IF(COUNTIFS('Data - Monthly Metrics'!A:A,$B$4,'Data - Monthly Metrics'!B:B,$E$4,'Data - Monthly Metrics'!C:C,"Majors/NRA",'Data - Monthly Metrics'!D:D,"New Members - Non-Target (#)")=0,"-",SUMIFS('Data - Monthly Metrics'!E:E,'Data - Monthly Metrics'!A:A,$B$4,'Data - Monthly Metrics'!B:B,$E$4,'Data - Monthly Metrics'!C:C,"Majors/NRA",'Data - Monthly Metrics'!D:D,"New Members - Non-Target (#)")) | I18: =IF(COUNTIFS('Data - Monthly Metrics'!A:A,$B$4,'Data - Monthly Metrics'!B:B,$E$4,'Data - Monthly Metrics'!C:C,"Majors/NRA",'Data - Monthly Metrics'!D:D,"Drops - Target (#)")=0,"-",SUMIFS('Data - Monthly Metrics'!E:E,'Data - Monthly Metrics'!A:A,$B$4,'Data - Monthly Metrics'!B:B,$E$4,'Data - Monthly Metrics'!C:C,"Majors/NRA",'Data - Monthly Metrics'!D:D,"Drops - Target (#)")) | J18: =IF(COUNTIFS('Data - Monthly Metrics'!A:A,$B$4,'Data - Monthly Metrics'!B:B,$E$4,'Data - Monthly Metrics'!C:C,"Majors/NRA",'Data - Monthly Metrics'!D:D,"Drops - Non-Target (#)")=0,"-",SUMIFS('Data - Monthly Metrics'!E:E,'Data - Monthly Metrics'!A:A,$B$4,'Data - Monthly Metrics'!B:B,$E$4,'Data - Monthly Metrics'!C:C,"Majors/NRA",'Data - Monthly Metrics'!D:D,"Drops - Non-Target (#)")) | K18: =IFERROR((SUMIFS('Data - Monthly Metrics'!E:E,'Data - Monthly Metrics'!A:A,$B$4,'Data - Monthly Metrics'!B:B,$E$4,'Data - Monthly Metrics'!C:C,"Majors/NRA",'Data - Monthly Metrics'!D:D,"Revenue Retained - Target ($)")+SUMIFS('Data - Monthly Metrics'!E:E,'Data - Monthly Metrics'!A:A,$B$4,'Data - Monthly Metrics'!B:B,$E$4,'Data - Monthly Metrics'!C:C,"Majors/NRA",'Data - Monthly Metrics'!D:D,"Revenue Retained - Non-Target ($)"))/(SUMIFS('Data - Monthly Metrics'!E:E,'Data - Monthly Metrics'!A:A,$B$4,'Data - Monthly Metrics'!B:B,$E$4,'Data - Monthly Metrics'!C:C,"Majors/NRA",'Data - Monthly Metrics'!D:D,"Revenue Up for Renewal - Target ($)")+SUMIFS('Data - Monthly Metrics'!E:E,'Data - Monthly Metrics'!A:A,$B$4,'Data - Monthly Metrics'!B:B,$E$4,'Data - Monthly Metrics'!C:C,"Majors/NRA",'Data - Monthly Metrics'!D:D,"Revenue Up for Renewal - Non-Target ($)")),"-") | L18: =IF(COUNTIFS('Data - Monthly Metrics'!A:A,$B$4,'Data - Monthly Metrics'!B:B,$E$4,'Data - Monthly Metrics'!C:C,"Majors/NRA",'Data - Monthly Metrics'!D:D,"Penetration - Combined %")=0,"-",SUMIFS('Data - Monthly Metrics'!E:E,'Data - Monthly Metrics'!A:A,$B$4,'Data - Monthly Metrics'!B:B,$E$4,'Data - Monthly Metrics'!C:C,"Majors/NRA",'Data - Monthly Metrics'!D:D,"Penetration - Combined %")) | M18: =IFERROR((SUMIFS('Data - Monthly Metrics'!E:E,'Data - Monthly Metrics'!A:A,$B$4,'Data - Monthly Metrics'!B:B,$E$4,'Data - Monthly Metrics'!C:C,"Majors/NRA",'Data - Monthly Metrics'!D:D,"Members Retained - Target (#)")+SUMIFS('Data - Monthly Metrics'!E:E,'Data - Monthly Metrics'!A:A,$B$4,'Data - Monthly Metrics'!B:B,$E$4,'Data - Monthly Metrics'!C:C,"Majors/NRA",'Data - Monthly Metrics'!D:D,"Members Retained - Non-Target (#)"))/(SUMIFS('Data - Monthly Metrics'!E:E,'Data - Monthly Metrics'!A:A,$B$4,'Data - Monthly Metrics'!B:B,$E$4,'Data - Monthly Metrics'!C:C,"Majors/NRA",'Data - Monthly Metrics'!D:D,"Members Up for Renewal - Target (#)")+SUMIFS('Data - Monthly Metrics'!E:E,'Data - Monthly Metrics'!A:A,$B$4,'Data - Monthly Metrics'!B:B,$E$4,'Data - Monthly Metrics'!C:C,"Majors/NRA",'Data - Monthly Metrics'!D:D,"Members Up for Renewal - Non-Target (#)")),"-")
